Workbook

Sheet Documentation
A1: Molly's Makeup Shop
A3: Author | B3: Marcelo Andrada Batista
A4: Date | B4: 45609

Sheet Summary Sales
A1: Molly's Makeup Shop
A2: Summary Sales
B3: Jan | C3: Feb | D3: Mar | E3: Apr | F3: May | G3: Jun | H3: Jul | I3: Aug | J3: Sep | K3: Oct | L3: Nov | M3: Dec | N3: Totals
A4: Blush | B4: =Chicago!B4+Cleveland!B4+LosAngeles!B4 -> 4098.42 | C4: =Chicago!C4+Cleveland!C4+LosAngeles!C4 -> 3965.87 | D4: =Chicago!D4+Cleveland!D4+LosAngeles!D4 -> 2862.71 | E4: =Chicago!E4+Cleveland!E4+LosAngeles!E4 -> 3951.03 | F4: =Chicago!F4+Cleveland!F4+LosAngeles!F4 -> 4138.46 | G4: =Chicago!G4+Cleveland!G4+LosAngeles!G4 -> 3424.69 | H4: =Chicago!H4+Cleveland!H4+LosAngeles!H4 -> 3231.2 | I4: =Chicago!I4+Cleveland!I4+LosAngeles!I4 -> 4359.44 | ... M4: =Chicago!M4+Cleveland!M4+LosAngeles!M4 -> 4482.42 | N4: =SUM(B4:M4) -> 46193.88
A5: Eyeliner | B5: =Chicago!B5+Cleveland!B5+LosAngeles!B5 -> 3293.11 | C5: =Chicago!C5+Cleveland!C5+LosAngeles!C5 -> 3542.42 | D5: =Chicago!D5+Cleveland!D5+LosAngeles!D5 -> 4209.12 | E5: =Chicago!E5+Cleveland!E5+LosAngeles!E5 -> 4058.63 | F5: =Chicago!F5+Cleveland!F5+LosAngeles!F5 -> 3686.57 | G5: =Chicago!G5+Cleveland!G5+LosAngeles!G5 -> 3787.31 | H5: =Chicago!H5+Cleveland!H5+LosAngeles!H5 -> 3815.36 | I5: =Chicago!I5+Cleveland!I5+LosAngeles!I5 -> 2936.9 | ... M5: =Chicago!M5+Cleveland!M5+LosAngeles!M5 -> 3719.41 | N5: =SUM(B5:M5) -> 44874.8
A6: Foundation | B6: =Chicago!B6+Cleveland!B6+LosAngeles!B6 -> 3578.82 | C6: =Chicago!C6+Cleveland!C6+LosAngeles!C6 -> 3146.23 | D6: =Chicago!D6+Cleveland!D6+LosAngeles!D6 -> 3571 | E6: =Chicago!E6+Cleveland!E6+LosAngeles!E6 -> 3782.64 | F6: =Chicago!F6+Cleveland!F6+LosAngeles!F6 -> 3230.98 | G6: =Chicago!G6+Cleveland!G6+LosAngeles!G6 -> 3483.32 | H6: =Chicago!H6+Cleveland!H6+LosAngeles!H6 -> 3617.22 | I6: =Chicago!I6+Cleveland!I6+LosAngeles!I6 -> 3173.05 | ... M6: =Chicago!M6+Cleveland!M6+LosAngeles!M6 -> 3835.45 | N6: =SUM(B6:M6) -> 43780.4
A7: Highlighter | B7: =Chicago!B7+Cleveland!B7+LosAngeles!B7 -> 4097.04 | C7: =Chicago!C7+Cleveland!C7+LosAngeles!C7 -> 3979.56 | D7: =Chicago!D7+Cleveland!D7+LosAngeles!D7 -> 3480.34 | E7: =Chicago!E7+Cleveland!E7+LosAngeles!E7 -> 3266.18 | F7: =Chicago!F7+Cleveland!F7+LosAngeles!F7 -> 3184.32 | G7: =Chicago!G7+Cleveland!G7+LosAngeles!G7 -> 4083.41 | H7: =Chicago!H7+Cleveland!H7+LosAngeles!H7 -> 2929.03 | I7: =Chicago!I7+Cleveland!I7+LosAngeles!I7 -> 2749.38 | ... M7: =Chicago!M7+Cleveland!M7+LosAngeles!M7 -> 3033.34 | N7: =SUM(B7:M7) -> 42217.62
A8: Lipstick | B8: =Chicago!B8+Cleveland!B8+LosAngeles!B8 -> 3706.6 | C8: =Chicago!C8+Cleveland!C8+LosAngeles!C8 -> 3466.07 | D8: =Chicago!D8+Cleveland!D8+LosAngeles!D8 -> 3743.71 | E8: =Chicago!E8+Cleveland!E8+LosAngeles!E8 -> 3952.53 | F8: =Chicago!F8+Cleveland!F8+LosAngeles!F8 -> 3569.96 | G8: =Chicago!G8+Cleveland!G8+LosAngeles!G8 -> 3667.56 | H8: =Chicago!H8+Cleveland!H8+LosAngeles!H8 -> 3060.59 | I8: =Chicago!I8+Cleveland!I8+LosAngeles!I8 -> 2776.66 | ... M8: =Chicago!M8+Cleveland!M8+LosAngeles!M8 -> 2995.39 | N8: =SUM(B8:M8) -> 41864.64
A9: Mascara | B9: =Chicago!B9+Cleveland!B9+LosAngeles!B9 -> 3440.73 | C9: =Chicago!C9+Cleveland!C9+LosAngeles!C9 -> 4079.39 | D9: =Chicago!D9+Cleveland!D9+LosAngeles!D9 -> 4233.17 | E9: =Chicago!E9+Cleveland!E9+LosAngeles!E9 -> 4266.87 | F9: =Chicago!F9+Cleveland!F9+LosAngeles!F9 -> 2861.23 | G9: =Chicago!G9+Cleveland!G9+LosAngeles!G9 -> 3406.36 | H9: =Chicago!H9+Cleveland!H9+LosAngeles!H9 -> 2488.56 | I9: =Chicago!I9+Cleveland!I9+LosAngeles!I9 -> 3921.75 | ... M9: =Chicago!M9+Cleveland!M9+LosAngeles!M9 -> 3714.2 | N9: =SUM(B9:M9) -> 43241.27
A10: Totals | B10: =Chicago!B10+Cleveland!B10+LosAngeles!B10 -> 22214.72 | C10: =Chicago!C10+Cleveland!C10+LosAngeles!C10 -> 22179.54 | D10: =Chicago!D10+Cleveland!D10+LosAngeles!D10 -> 22100.05 | E10: =Chicago!E10+Cleveland!E10+LosAngeles!E10 -> 23277.88 | F10: =Chicago!F10+Cleveland!F10+LosAngeles!F10 -> 20671.52 | G10: =Chicago!G10+Cleveland!G10+LosAngeles!G10 -> 21852.65 | H10: =Chicago!H10+Cleveland!H10+LosAngeles!H10 -> 19141.96 | I10: =Chicago!I10+Cleveland!I10+LosAngeles!I10 -> 19917.18 | ... M10: =Chicago!M10+Cleveland!M10+LosAngeles!M10 -> 21780.21 | N10: =SUM(B10:M10) -> 262172.61

Sheet Chicago
A1: Molly's Makeup Shop
A2: Chicago
B3: Jan | C3: Feb | D3: Mar | E3: Apr | F3: May | G3: Jun | H3: Jul | I3: Aug | J3: Sep | K3: Oct | L3: Nov | M3: Dec | N3: Totals
A4: Blush | B4: 1366.14 | C4: 1462.51 | D4: 976.69 | E4: 1313.8 | F4: 1420.24 | G4: 931.94 | H4: 957.34 | I4: 1080.63 | J4: 1039.62 | K4: 808.97 | L4: 1076.64 | M4: 1374 | N4: =SUM(B4:M4) -> 13808.52
A5: Eyeliner | B5: 1187.1 | C5: 1062.7 | D5: 1474.41 | E5: 860.45 | F5: 1478.27 | G5: 1137.06 | H5: 1318.96 | I5: 969.6 | J5: 892.77 | K5: 1356.44 | L5: 1418.64 | M5: 1106.25 | N5: =SUM(B5:M5) -> 14262.65
A6: Foundation | B6: 948.06 | C6: 1126.53 | D6: 1073.25 | E6: 934.51 | F6: 858.36 | G6: 879.88 | H6: 1430.67 | I6: 1068.18 | J6: 1395.62 | K6: 917.13 | L6: 1197.79 | M6: 1299.04 | N6: =SUM(B6:M6) -> 13129.02
A7: Highlighter | B7: 1212.67 | C7: 1483.9 | D7: 919.99 | E7: 1095.72 | F7: 1000.1 | G7: 1114.16 | H7: 1065.96 | I7: 812.87 | J7: 1367.31 | K7: 1487.29 | L7: 1360.65 | M7: 957.91 | N7: =SUM(B7:M7) -> 13878.53
A8: Lipstick | B8: 1432.75 | C8: 912.45 | D8: 1427.14 | E8: 1065.59 | F8: 999.34 | G8: 1494.52 | H8: 860.38 | I8: 1128.35 | J8: 1092.8 | K8: 1454.92 | L8: 995.83 | M8: 940.76 | N8: =SUM(B8:M8) -> 13804.83
A9: Mascara | B9: 896.13 | C9: 1232.7 | D9: 1039.52 | E9: 1381.54 | F9: 978.52 | G9: 924 | H9: 861.57 | I9: 1277.19 | J9: 1312.6 | K9: 1124.23 | L9: 1036.48 | M9: 1146.89 | N9: =SUM(B9:M9) -> 13211.37
A10: Totals | B10: =SUM(B4:B9) -> 7042.85 | C10: =SUM(C4:C9) -> 7280.79 | D10: =SUM(D4:D9) -> 6911 | E10: =SUM(E4:E9) -> 6651.61 | F10: =SUM(F4:F9) -> 6734.83 | G10: =SUM(G4:G9) -> 6481.56 | H10: =SUM(H4:H9) -> 6494.88 | I10: =SUM(I4:I9) -> 6336.82 | ... M10: =SUM(M4:M9) -> 6824.85 | N10: =SUM(B10:M10) -> 82094.92

Sheet Cleveland
A1: Molly's Makeup Shop
A2: Cleveland
B3: Jan | C3: Feb | D3: Mar | E3: Apr | F3: May | G3: Jun | H3: Jul | I3: Aug | J3: Sep | K3: Oct | L3: Nov | M3: Dec | N3: Totals
A4: Blush | B4: 1366.14 | C4: 852.37 | D4: 785.96 | E4: 948.55 | F4: 1146.9 | G4: 1162.84 | H4: 742.11 | I4: 1109.38 | J4: 836.86 | K4: 930.49 | L4: 730.02 | M4: 1064.31 | N4: =SUM(B4:M4) -> 11675.93
A5: Eyeliner | B5: 887.46 | C5: 980.48 | D5: 713.45 | E5: 1167.02 | F5: 911.03 | G5: 771.21 | H5: 1047.07 | I5: 906.22 | J5: 1104.53 | K5: 1081.05 | L5: 797.71 | M5: 1197.27 | N5: =SUM(B5:M5) -> 11564.5
A6: Foundation | B6: 1194.76 | C6: 1145.96 | D6: 811.29 | E6: 1093.83 | F6: 746 | G6: 1042.66 | H6: 969.84 | I6: 885.46 | J6: 881.79 | K6: 1094.77 | L6: 1075.62 | M6: 915.78 | N6: =SUM(B6:M6) -> 11857.76
A7: Highlighter | B7: 752.23 | C7: 993.28 | D7: 1159.24 | E7: 1089.75 | F7: 1025.72 | G7: 898.97 | H7: 1032.21 | I7: 1126.36 | J7: 994.08 | K7: 912.55 | L7: 802.13 | M7: 890.74 | N7: =SUM(B7:M7) -> 11677.26
A8: Lipstick | B8: 1095.6 | C8: 1102.28 | D8: 1114.04 | E8: 1118.72 | F8: 924.55 | G8: 1193.11 | H8: 1009.9 | I8: 704.02 | J8: 757.67 | K8: 773.16 | L8: 1189.04 | M8: 871.47 | N8: =SUM(B8:M8) -> 11853.56
A9: Mascara | B9: 738.11 | C9: 794.74 | D9: 1158.15 | E9: 807.55 | F9: 855.53 | G9: 1003.22 | H9: 753.17 | I9: 851.26 | J9: 889.39 | K9: 740.29 | L9: 854.52 | M9: 789.67 | N9: =SUM(B9:M9) -> 10235.6
A10: Totals | B10: =SUM(B4:B9) -> 6034.3 | C10: =SUM(C4:C9) -> 5869.11 | D10: =SUM(D4:D9) -> 5742.13 | E10: =SUM(E4:E9) -> 6225.42 | F10: =SUM(F4:F9) -> 5609.73 | G10: =SUM(G4:G9) -> 6072.01 | H10: =SUM(H4:H9) -> 5554.3 | I10: =SUM(I4:I9) -> 5582.7 | ... M10: =SUM(M4:M9) -> 5729.24 | N10: =SUM(B10:M10) -> 68864.61

Sheet LosAngeles
A1: Molly's Makeup Shop
A2: Los Angeles
B3: Jan | C3: Feb | D3: Mar | E3: Apr | F3: May | G3: Jun | H3: Jul | I3: Aug | J3: Sep | K3: Oct | L3: Nov | M3: Dec | N3: Totals
A4: Blush | B4: 1366.14 | C4: 1650.99 | D4: 1100.06 | E4: 1688.68 | F4: 1571.32 | G4: 1329.91 | H4: 1531.75 | I4: 2169.43 | J4: 2146.33 | K4: 2045.71 | L4: 2065 | M4: 2044.11 | N4: =SUM(B4:M4) -> 20709.43
A5: Eyeliner | B5: 1218.55 | C5: 1499.24 | D5: 2021.26 | E5: 2031.16 | F5: 1297.27 | G5: 1879.04 | H5: 1449.33 | I5: 1061.08 | J5: 1824.83 | K5: 1290.58 | L5: 2059.42 | M5: 1415.89 | N5: =SUM(B5:M5) -> 19047.65
A6: Foundation | B6: 1436 | C6: 873.74 | D6: 1686.46 | E6: 1754.3 | F6: 1626.62 | G6: 1560.78 | H6: 1216.71 | I6: 1219.41 | J6: 2148.08 | K6: 1628.59 | L6: 2022.3 | M6: 1620.63 | N6: =SUM(B6:M6) -> 18793.62
A7: Highlighter | B7: 2132.14 | C7: 1502.38 | D7: 1401.11 | E7: 1080.71 | F7: 1158.5 | G7: 2070.28 | H7: 830.86 | I7: 810.15 | J7: 1610.89 | K7: 935.93 | L7: 1944.19 | M7: 1184.69 | N7: =SUM(B7:M7) -> 16661.83
A8: Lipstick | B8: 1178.25 | C8: 1451.34 | D8: 1202.53 | E8: 1768.22 | F8: 1646.07 | G8: 979.93 | H8: 1190.31 | I8: 944.29 | J8: 2164.79 | K8: 1678.37 | L8: 818.99 | M8: 1183.16 | N8: =SUM(B8:M8) -> 16206.25
A9: Mascara | B9: 1806.49 | C9: 2051.95 | D9: 2035.5 | E9: 2077.78 | F9: 1027.18 | G9: 1479.14 | H9: 873.82 | I9: 1793.3 | J9: 1718.78 | K9: 1522.96 | L9: 1629.76 | M9: 1777.64 | N9: =SUM(B9:M9) -> 19794.3
A10: Totals | B10: =SUM(B4:B9) -> 9137.57 | C10: =SUM(C4:C9) -> 9029.64 | D10: =SUM(D4:D9) -> 9446.92 | E10: =SUM(E4:E9) -> 10400.85 | F10: =SUM(F4:F9) -> 8326.96 | G10: =SUM(G4:G9) -> 9299.08 | H10: =SUM(H4:H9) -> 7092.78 | I10: =SUM(I4:I9) -> 7997.66 | ... M10: =SUM(M4:M9) -> 9226.12 | N10: =SUM(B10:M10) -> 111213.08

Sheet Pricing and Shipping
A1: Product Pricing
A2: Item | B2: Price
A3: Blush (1) 0.08 oz | B3: 15 | I3: Adjustable Home Bed Rail
A4: Eyeliner (1) 0.02 oz | B4: 22 | I4: Bed Cane
A5: Foundation (1) 0.5 oz | B5: 15 | I5: Doorknob Gripper
A6: Highlighter (1) 0.04 oz | B6: 19 | I6: Easy Grip Utensils
A7: Lipstick (1) 0.24 oz | B7: 9 | I7: Economy Patient Gowns
A8: Mascara (1) 0.17 oz | B8: 26 | I8: Full-Page Magnifier
A9: Blush (2) 0.08 oz | B9: 20 | I9: Giant TV Remote
A10: Eyeliner (2) 0.02 oz | B10: 28 | I10: Inflatable Shampoo Basin
A11: Foundation (2) 0.5 oz | B11: 20 | I11: Jar Opener
A12: Highlighter (2) 0.04 oz | B12: 22 | I12: Lamp Switch Enlarger
A13: Lipstick (2) 0.24 oz | B13: 12 | I13: Medication Dispenser
A14: Mascara (2) 0.17 oz | B14: 33 | I14: No Rinse Shampoo
... A17: Mascara (1) 0.4 oz | B17: 25 | I17: Wheelchair Poncho
A18: Foundation (1) 0.28 oz | B18: 30
A19: Highlighter (1) 0.085 oz | B19: 27
A20: Lipstick (1) 0.33 oz | B20: 12
A21: Mascara (1) 0.29 oz | B21: 33
A22: Blush (2) 0.17 oz | B22: 35
A23: Eyeliner (2) 0.04 oz | B23: 33
A24: Mascara (2) 0.4 oz | B24: 32
A25: Foundation (2) 0.28 oz | B25: 35
A26: Highlighter (2) 0.085 oz | B26: 37
A27: Lipstick (2) 0.33 oz | B27: 16
A28: Mascara (2) 0.29 oz | B28: 39

Sheet Customer Invoice
B2: Molly's Make Up Shop
B3: 2534 West Main
B4: Chicago,Illinois 60603
B5: (312) 444-1313
B6: Date Sold:
B7: 45609
B9: Sold to:
B10: Jenny Rose | E10: <-Name
B11: 1241 State Street | E11: <-Street
B12: Chicago | C12: IL | D12: 60611 | E12: <-City, State, Zip
B15: Item | E15: Color | F15: Qty | G15: Price | H15: Total
B16: Mascara (1) 0.17 oz | E16: Blue | F16: 1 | G16: =IFERROR(VLOOKUP(B16, 'Pricing and Shipping'!$A$2:$B$10, 2, FALSE), "Select an item") -> 26 | H16: =IFERROR(F16 * G16, "") -> 26
B17: Foundation (1) 0.5 oz | E17: Medium to Deep | F17: 1 | G17: =IFERROR(VLOOKUP(B17, 'Pricing and Shipping'!$A$2:$B$10, 2, FALSE), "Select an item") -> 15 | H17: =IFERROR(F17 * G17, "") -> 15
B18: Lipstick (1) 0.24 oz | E18: Deep Red | F18: 2 | G18: =IFERROR(VLOOKUP(B18, 'Pricing and Shipping'!$A$2:$B$10, 2, FALSE), "Select an item") -> 9 | H18: =IFERROR(F18 * G18, "") -> 18
G19: =IFERROR(VLOOKUP(B19, 'Pricing and Shipping'!$A$2:$B$10, 2, FALSE), "Select an item") -> Select an item | H19: =IFERROR(F19 * G19, "")
G20: =IFERROR(VLOOKUP(B20, 'Pricing and Shipping'!$A$2:$B$10, 2, FALSE), "Select an item") -> Select an item | H20: =IFERROR(F20 * G20, "")
G21: =IFERROR(VLOOKUP(B21, 'Pricing and Shipping'!$A$2:$B$10, 2, FALSE), "Select an item") -> Select an item | H21: =IFERROR(F21 * G21, "")
G22: =IFERROR(VLOOKUP(B22, 'Pricing and Shipping'!$A$2:$B$10, 2, FALSE), "Select an item") -> Select an item | H22: =IFERROR(F22 * G22, "")
G23: =IFERROR(VLOOKUP(B23, 'Pricing and Shipping'!$A$2:$B$10, 2, FALSE), "Select an item") -> Select an item | H23: =IFERROR(F23 * G23, "")
G24: =IFERROR(VLOOKUP(B24, 'Pricing and Shipping'!$A$2:$B$10, 2, FALSE), "Select an item") -> Select an item | H24: =IFERROR(F24 * G24, "")
G25: =IFERROR(VLOOKUP(B25, 'Pricing and Shipping'!$A$2:$B$10, 2, FALSE), "Select an item") -> Select an item | H25: =IFERROR(F25 * G25, "")
G26: =IFERROR(VLOOKUP(B26, 'Pricing and Shipping'!$A$2:$B$10, 2, FALSE), "Select an item") -> Select an item | H26: =IFERROR(F26 * G26, "")
B27: Notes: | G27: Subtotal | H27: =IFERROR(SUM(H16:H26), "") -> 59
G28: Sales Tax | H28: =IF(C12 = "IL", H27 * 0.07, 0) -> 4.13
G29: Shipping | H29: =IF(SUM(F16:F26) < 3, 3, 0) -> 0
G30: Total Due | H30: =H27 + H28 + H29 -> 63.13
B32: COLOR OPTIONS
B33: Blush | D33: Foundation | E33: Highlighter | F33: Lipstick | H33: Mascara
B34: Apricot Dream | D34: Deep | E34: Apricot | F34: Canary Yellow | H34: Black
B35: Deep Red | D35: Fair | E35: Canary | F35: Deep Blue | H35: Blue
B36: Peach | D36: Fair to Medium | E36: Disco Days | F36: Deep Red | H36: Midnight
B37: Peonie Pink | D37: Medium | E37: Gold | F37: Light Pink | H37: Purple
B38: Raspberry | D38: Medium | E38: Peach Dreams | F38: Nude | H38: Red
B39: Strawberry Red | D39: Medium to Deep | E39: Pink | F39: Peonie Pink | H39: White
B40: Sunrise | D40: Porcelain | E40: Strobe | F40: Purple | H40: Eyeliner
B41: Sunset Orange | D41: Very Fair | E41: Sunrise | F41: Red | H41: Black
B42: Tangerine | E42: Sunset | F42: Sky Blue | H42: Canary Yellow
B43: Warm Desert | E43: Tangerine | F43: Sunset Orange | H43: Charcoal
E44: Unicorn | F44: Midnight | H44: Deep Blue
H45: Grey
...
